{
 "cells": [
  {
   "cell_type": "code",
   "execution_count": 1,
   "metadata": {},
   "outputs": [
    {
     "name": "stdout",
     "output_type": "stream",
     "text": [
      "Jupyter environment detected. Enabling Open3D WebVisualizer.\n",
      "[Open3D INFO] WebRTC GUI backend enabled.\n",
      "[Open3D INFO] WebRTCWindowSystem: HTTP handshake server disabled.\n"
     ]
    }
   ],
   "source": [
    "import laspy\n",
    "import open3d as o3d\n",
    "import numpy as np"
   ]
  },
  {
   "cell_type": "code",
   "execution_count": 2,
   "metadata": {},
   "outputs": [],
   "source": [
    "import sys, os\n",
    "sys.path.append(os.path.abspath(os.path.join('../scripts')))"
   ]
  },
  {
   "cell_type": "code",
   "execution_count": 46,
   "metadata": {},
   "outputs": [
    {
     "name": "stdout",
     "output_type": "stream",
     "text": [
      "2022-06-24 23:36:50,477 — FileHandler — ERROR — usgs_3dep_metadata not found\n",
      "Traceback (most recent call last):\n",
      "  File \"c:\\Users\\user\\10-Accademy\\W7\\USGS_3DEP_Python_LIDAR\\scripts\\file_handler.py\", line 49, in read_csv\n",
      "    path = logger.DATAS_PATH / str(name + '.csv')\n",
      "  File \"c:\\Users\\user\\.conda\\envs\\pdalpy_n\\lib\\site-packages\\pandas\\util\\_decorators.py\", line 311, in wrapper\n",
      "    return func(*args, **kwargs)\n",
      "  File \"c:\\Users\\user\\.conda\\envs\\pdalpy_n\\lib\\site-packages\\pandas\\io\\parsers\\readers.py\", line 680, in read_csv\n",
      "    return _read(filepath_or_buffer, kwds)\n",
      "  File \"c:\\Users\\user\\.conda\\envs\\pdalpy_n\\lib\\site-packages\\pandas\\io\\parsers\\readers.py\", line 575, in _read\n",
      "    parser = TextFileReader(filepath_or_buffer, **kwds)\n",
      "  File \"c:\\Users\\user\\.conda\\envs\\pdalpy_n\\lib\\site-packages\\pandas\\io\\parsers\\readers.py\", line 933, in __init__\n",
      "    self._engine = self._make_engine(f, self.engine)\n",
      "  File \"c:\\Users\\user\\.conda\\envs\\pdalpy_n\\lib\\site-packages\\pandas\\io\\parsers\\readers.py\", line 1217, in _make_engine\n",
      "    self.handles = get_handle(  # type: ignore[call-overload]\n",
      "  File \"c:\\Users\\user\\.conda\\envs\\pdalpy_n\\lib\\site-packages\\pandas\\io\\common.py\", line 789, in get_handle\n",
      "    handle = open(\n",
      "FileNotFoundError: [Errno 2] No such file or directory: '..\\\\assets\\\\usgs_3dep_metadata.csv'\n",
      "2022-06-24 23:36:50,477 — FileHandler — ERROR — usgs_3dep_metadata not found\n",
      "Traceback (most recent call last):\n",
      "  File \"c:\\Users\\user\\10-Accademy\\W7\\USGS_3DEP_Python_LIDAR\\scripts\\file_handler.py\", line 49, in read_csv\n",
      "    path = logger.DATAS_PATH / str(name + '.csv')\n",
      "  File \"c:\\Users\\user\\.conda\\envs\\pdalpy_n\\lib\\site-packages\\pandas\\util\\_decorators.py\", line 311, in wrapper\n",
      "    return func(*args, **kwargs)\n",
      "  File \"c:\\Users\\user\\.conda\\envs\\pdalpy_n\\lib\\site-packages\\pandas\\io\\parsers\\readers.py\", line 680, in read_csv\n",
      "    return _read(filepath_or_buffer, kwds)\n",
      "  File \"c:\\Users\\user\\.conda\\envs\\pdalpy_n\\lib\\site-packages\\pandas\\io\\parsers\\readers.py\", line 575, in _read\n",
      "    parser = TextFileReader(filepath_or_buffer, **kwds)\n",
      "  File \"c:\\Users\\user\\.conda\\envs\\pdalpy_n\\lib\\site-packages\\pandas\\io\\parsers\\readers.py\", line 933, in __init__\n",
      "    self._engine = self._make_engine(f, self.engine)\n",
      "  File \"c:\\Users\\user\\.conda\\envs\\pdalpy_n\\lib\\site-packages\\pandas\\io\\parsers\\readers.py\", line 1217, in _make_engine\n",
      "    self.handles = get_handle(  # type: ignore[call-overload]\n",
      "  File \"c:\\Users\\user\\.conda\\envs\\pdalpy_n\\lib\\site-packages\\pandas\\io\\common.py\", line 789, in get_handle\n",
      "    handle = open(\n",
      "FileNotFoundError: [Errno 2] No such file or directory: '..\\\\assets\\\\usgs_3dep_metadata.csv'\n",
      "2022-06-24 23:36:50,477 — FileHandler — ERROR — usgs_3dep_metadata not found\n",
      "Traceback (most recent call last):\n",
      "  File \"c:\\Users\\user\\10-Accademy\\W7\\USGS_3DEP_Python_LIDAR\\scripts\\file_handler.py\", line 49, in read_csv\n",
      "    path = logger.DATAS_PATH / str(name + '.csv')\n",
      "  File \"c:\\Users\\user\\.conda\\envs\\pdalpy_n\\lib\\site-packages\\pandas\\util\\_decorators.py\", line 311, in wrapper\n",
      "    return func(*args, **kwargs)\n",
      "  File \"c:\\Users\\user\\.conda\\envs\\pdalpy_n\\lib\\site-packages\\pandas\\io\\parsers\\readers.py\", line 680, in read_csv\n",
      "    return _read(filepath_or_buffer, kwds)\n",
      "  File \"c:\\Users\\user\\.conda\\envs\\pdalpy_n\\lib\\site-packages\\pandas\\io\\parsers\\readers.py\", line 575, in _read\n",
      "    parser = TextFileReader(filepath_or_buffer, **kwds)\n",
      "  File \"c:\\Users\\user\\.conda\\envs\\pdalpy_n\\lib\\site-packages\\pandas\\io\\parsers\\readers.py\", line 933, in __init__\n",
      "    self._engine = self._make_engine(f, self.engine)\n",
      "  File \"c:\\Users\\user\\.conda\\envs\\pdalpy_n\\lib\\site-packages\\pandas\\io\\parsers\\readers.py\", line 1217, in _make_engine\n",
      "    self.handles = get_handle(  # type: ignore[call-overload]\n",
      "  File \"c:\\Users\\user\\.conda\\envs\\pdalpy_n\\lib\\site-packages\\pandas\\io\\common.py\", line 789, in get_handle\n",
      "    handle = open(\n",
      "FileNotFoundError: [Errno 2] No such file or directory: '..\\\\assets\\\\usgs_3dep_metadata.csv'\n",
      "2022-06-24 23:36:50,477 — FileHandler — ERROR — usgs_3dep_metadata not found\n",
      "Traceback (most recent call last):\n",
      "  File \"c:\\Users\\user\\10-Accademy\\W7\\USGS_3DEP_Python_LIDAR\\scripts\\file_handler.py\", line 49, in read_csv\n",
      "    path = logger.DATAS_PATH / str(name + '.csv')\n",
      "  File \"c:\\Users\\user\\.conda\\envs\\pdalpy_n\\lib\\site-packages\\pandas\\util\\_decorators.py\", line 311, in wrapper\n",
      "    return func(*args, **kwargs)\n",
      "  File \"c:\\Users\\user\\.conda\\envs\\pdalpy_n\\lib\\site-packages\\pandas\\io\\parsers\\readers.py\", line 680, in read_csv\n",
      "    return _read(filepath_or_buffer, kwds)\n",
      "  File \"c:\\Users\\user\\.conda\\envs\\pdalpy_n\\lib\\site-packages\\pandas\\io\\parsers\\readers.py\", line 575, in _read\n",
      "    parser = TextFileReader(filepath_or_buffer, **kwds)\n",
      "  File \"c:\\Users\\user\\.conda\\envs\\pdalpy_n\\lib\\site-packages\\pandas\\io\\parsers\\readers.py\", line 933, in __init__\n",
      "    self._engine = self._make_engine(f, self.engine)\n",
      "  File \"c:\\Users\\user\\.conda\\envs\\pdalpy_n\\lib\\site-packages\\pandas\\io\\parsers\\readers.py\", line 1217, in _make_engine\n",
      "    self.handles = get_handle(  # type: ignore[call-overload]\n",
      "  File \"c:\\Users\\user\\.conda\\envs\\pdalpy_n\\lib\\site-packages\\pandas\\io\\common.py\", line 789, in get_handle\n",
      "    handle = open(\n",
      "FileNotFoundError: [Errno 2] No such file or directory: '..\\\\assets\\\\usgs_3dep_metadata.csv'\n",
      "2022-06-24 23:36:50,477 — FileHandler — ERROR — usgs_3dep_metadata not found\n",
      "Traceback (most recent call last):\n",
      "  File \"c:\\Users\\user\\10-Accademy\\W7\\USGS_3DEP_Python_LIDAR\\scripts\\file_handler.py\", line 49, in read_csv\n",
      "    path = logger.DATAS_PATH / str(name + '.csv')\n",
      "  File \"c:\\Users\\user\\.conda\\envs\\pdalpy_n\\lib\\site-packages\\pandas\\util\\_decorators.py\", line 311, in wrapper\n",
      "    return func(*args, **kwargs)\n",
      "  File \"c:\\Users\\user\\.conda\\envs\\pdalpy_n\\lib\\site-packages\\pandas\\io\\parsers\\readers.py\", line 680, in read_csv\n",
      "    return _read(filepath_or_buffer, kwds)\n",
      "  File \"c:\\Users\\user\\.conda\\envs\\pdalpy_n\\lib\\site-packages\\pandas\\io\\parsers\\readers.py\", line 575, in _read\n",
      "    parser = TextFileReader(filepath_or_buffer, **kwds)\n",
      "  File \"c:\\Users\\user\\.conda\\envs\\pdalpy_n\\lib\\site-packages\\pandas\\io\\parsers\\readers.py\", line 933, in __init__\n",
      "    self._engine = self._make_engine(f, self.engine)\n",
      "  File \"c:\\Users\\user\\.conda\\envs\\pdalpy_n\\lib\\site-packages\\pandas\\io\\parsers\\readers.py\", line 1217, in _make_engine\n",
      "    self.handles = get_handle(  # type: ignore[call-overload]\n",
      "  File \"c:\\Users\\user\\.conda\\envs\\pdalpy_n\\lib\\site-packages\\pandas\\io\\common.py\", line 789, in get_handle\n",
      "    handle = open(\n",
      "FileNotFoundError: [Errno 2] No such file or directory: '..\\\\assets\\\\usgs_3dep_metadata.csv'\n",
      "2022-06-24 23:36:50,477 — FileHandler — ERROR — usgs_3dep_metadata not found\n",
      "Traceback (most recent call last):\n",
      "  File \"c:\\Users\\user\\10-Accademy\\W7\\USGS_3DEP_Python_LIDAR\\scripts\\file_handler.py\", line 49, in read_csv\n",
      "    path = logger.DATAS_PATH / str(name + '.csv')\n",
      "  File \"c:\\Users\\user\\.conda\\envs\\pdalpy_n\\lib\\site-packages\\pandas\\util\\_decorators.py\", line 311, in wrapper\n",
      "    return func(*args, **kwargs)\n",
      "  File \"c:\\Users\\user\\.conda\\envs\\pdalpy_n\\lib\\site-packages\\pandas\\io\\parsers\\readers.py\", line 680, in read_csv\n",
      "    return _read(filepath_or_buffer, kwds)\n",
      "  File \"c:\\Users\\user\\.conda\\envs\\pdalpy_n\\lib\\site-packages\\pandas\\io\\parsers\\readers.py\", line 575, in _read\n",
      "    parser = TextFileReader(filepath_or_buffer, **kwds)\n",
      "  File \"c:\\Users\\user\\.conda\\envs\\pdalpy_n\\lib\\site-packages\\pandas\\io\\parsers\\readers.py\", line 933, in __init__\n",
      "    self._engine = self._make_engine(f, self.engine)\n",
      "  File \"c:\\Users\\user\\.conda\\envs\\pdalpy_n\\lib\\site-packages\\pandas\\io\\parsers\\readers.py\", line 1217, in _make_engine\n",
      "    self.handles = get_handle(  # type: ignore[call-overload]\n",
      "  File \"c:\\Users\\user\\.conda\\envs\\pdalpy_n\\lib\\site-packages\\pandas\\io\\common.py\", line 789, in get_handle\n",
      "    handle = open(\n",
      "FileNotFoundError: [Errno 2] No such file or directory: '..\\\\assets\\\\usgs_3dep_metadata.csv'\n",
      "2022-06-24 23:36:50,477 — FileHandler — ERROR — usgs_3dep_metadata not found\n",
      "Traceback (most recent call last):\n",
      "  File \"c:\\Users\\user\\10-Accademy\\W7\\USGS_3DEP_Python_LIDAR\\scripts\\file_handler.py\", line 49, in read_csv\n",
      "    path = logger.DATAS_PATH / str(name + '.csv')\n",
      "  File \"c:\\Users\\user\\.conda\\envs\\pdalpy_n\\lib\\site-packages\\pandas\\util\\_decorators.py\", line 311, in wrapper\n",
      "    return func(*args, **kwargs)\n",
      "  File \"c:\\Users\\user\\.conda\\envs\\pdalpy_n\\lib\\site-packages\\pandas\\io\\parsers\\readers.py\", line 680, in read_csv\n",
      "    return _read(filepath_or_buffer, kwds)\n",
      "  File \"c:\\Users\\user\\.conda\\envs\\pdalpy_n\\lib\\site-packages\\pandas\\io\\parsers\\readers.py\", line 575, in _read\n",
      "    parser = TextFileReader(filepath_or_buffer, **kwds)\n",
      "  File \"c:\\Users\\user\\.conda\\envs\\pdalpy_n\\lib\\site-packages\\pandas\\io\\parsers\\readers.py\", line 933, in __init__\n",
      "    self._engine = self._make_engine(f, self.engine)\n",
      "  File \"c:\\Users\\user\\.conda\\envs\\pdalpy_n\\lib\\site-packages\\pandas\\io\\parsers\\readers.py\", line 1217, in _make_engine\n",
      "    self.handles = get_handle(  # type: ignore[call-overload]\n",
      "  File \"c:\\Users\\user\\.conda\\envs\\pdalpy_n\\lib\\site-packages\\pandas\\io\\common.py\", line 789, in get_handle\n",
      "    handle = open(\n",
      "FileNotFoundError: [Errno 2] No such file or directory: '..\\\\assets\\\\usgs_3dep_metadata.csv'\n",
      "2022-06-24 23:36:50,477 — FileHandler — ERROR — usgs_3dep_metadata not found\n",
      "Traceback (most recent call last):\n",
      "  File \"c:\\Users\\user\\10-Accademy\\W7\\USGS_3DEP_Python_LIDAR\\scripts\\file_handler.py\", line 49, in read_csv\n",
      "    path = logger.DATAS_PATH / str(name + '.csv')\n",
      "  File \"c:\\Users\\user\\.conda\\envs\\pdalpy_n\\lib\\site-packages\\pandas\\util\\_decorators.py\", line 311, in wrapper\n",
      "    return func(*args, **kwargs)\n",
      "  File \"c:\\Users\\user\\.conda\\envs\\pdalpy_n\\lib\\site-packages\\pandas\\io\\parsers\\readers.py\", line 680, in read_csv\n",
      "    return _read(filepath_or_buffer, kwds)\n",
      "  File \"c:\\Users\\user\\.conda\\envs\\pdalpy_n\\lib\\site-packages\\pandas\\io\\parsers\\readers.py\", line 575, in _read\n",
      "    parser = TextFileReader(filepath_or_buffer, **kwds)\n",
      "  File \"c:\\Users\\user\\.conda\\envs\\pdalpy_n\\lib\\site-packages\\pandas\\io\\parsers\\readers.py\", line 933, in __init__\n",
      "    self._engine = self._make_engine(f, self.engine)\n",
      "  File \"c:\\Users\\user\\.conda\\envs\\pdalpy_n\\lib\\site-packages\\pandas\\io\\parsers\\readers.py\", line 1217, in _make_engine\n",
      "    self.handles = get_handle(  # type: ignore[call-overload]\n",
      "  File \"c:\\Users\\user\\.conda\\envs\\pdalpy_n\\lib\\site-packages\\pandas\\io\\common.py\", line 789, in get_handle\n",
      "    handle = open(\n",
      "FileNotFoundError: [Errno 2] No such file or directory: '..\\\\assets\\\\usgs_3dep_metadata.csv'\n",
      "2022-06-24 23:36:50,477 — FileHandler — ERROR — usgs_3dep_metadata not found\n",
      "Traceback (most recent call last):\n",
      "  File \"c:\\Users\\user\\10-Accademy\\W7\\USGS_3DEP_Python_LIDAR\\scripts\\file_handler.py\", line 49, in read_csv\n",
      "    path = logger.DATAS_PATH / str(name + '.csv')\n",
      "  File \"c:\\Users\\user\\.conda\\envs\\pdalpy_n\\lib\\site-packages\\pandas\\util\\_decorators.py\", line 311, in wrapper\n",
      "    return func(*args, **kwargs)\n",
      "  File \"c:\\Users\\user\\.conda\\envs\\pdalpy_n\\lib\\site-packages\\pandas\\io\\parsers\\readers.py\", line 680, in read_csv\n",
      "    return _read(filepath_or_buffer, kwds)\n",
      "  File \"c:\\Users\\user\\.conda\\envs\\pdalpy_n\\lib\\site-packages\\pandas\\io\\parsers\\readers.py\", line 575, in _read\n",
      "    parser = TextFileReader(filepath_or_buffer, **kwds)\n",
      "  File \"c:\\Users\\user\\.conda\\envs\\pdalpy_n\\lib\\site-packages\\pandas\\io\\parsers\\readers.py\", line 933, in __init__\n",
      "    self._engine = self._make_engine(f, self.engine)\n",
      "  File \"c:\\Users\\user\\.conda\\envs\\pdalpy_n\\lib\\site-packages\\pandas\\io\\parsers\\readers.py\", line 1217, in _make_engine\n",
      "    self.handles = get_handle(  # type: ignore[call-overload]\n",
      "  File \"c:\\Users\\user\\.conda\\envs\\pdalpy_n\\lib\\site-packages\\pandas\\io\\common.py\", line 789, in get_handle\n",
      "    handle = open(\n",
      "FileNotFoundError: [Errno 2] No such file or directory: '..\\\\assets\\\\usgs_3dep_metadata.csv'\n",
      "2022-06-24 23:36:50,477 — FileHandler — ERROR — usgs_3dep_metadata not found\n",
      "Traceback (most recent call last):\n",
      "  File \"c:\\Users\\user\\10-Accademy\\W7\\USGS_3DEP_Python_LIDAR\\scripts\\file_handler.py\", line 49, in read_csv\n",
      "    path = logger.DATAS_PATH / str(name + '.csv')\n",
      "  File \"c:\\Users\\user\\.conda\\envs\\pdalpy_n\\lib\\site-packages\\pandas\\util\\_decorators.py\", line 311, in wrapper\n",
      "    return func(*args, **kwargs)\n",
      "  File \"c:\\Users\\user\\.conda\\envs\\pdalpy_n\\lib\\site-packages\\pandas\\io\\parsers\\readers.py\", line 680, in read_csv\n",
      "    return _read(filepath_or_buffer, kwds)\n",
      "  File \"c:\\Users\\user\\.conda\\envs\\pdalpy_n\\lib\\site-packages\\pandas\\io\\parsers\\readers.py\", line 575, in _read\n",
      "    parser = TextFileReader(filepath_or_buffer, **kwds)\n",
      "  File \"c:\\Users\\user\\.conda\\envs\\pdalpy_n\\lib\\site-packages\\pandas\\io\\parsers\\readers.py\", line 933, in __init__\n",
      "    self._engine = self._make_engine(f, self.engine)\n",
      "  File \"c:\\Users\\user\\.conda\\envs\\pdalpy_n\\lib\\site-packages\\pandas\\io\\parsers\\readers.py\", line 1217, in _make_engine\n",
      "    self.handles = get_handle(  # type: ignore[call-overload]\n",
      "  File \"c:\\Users\\user\\.conda\\envs\\pdalpy_n\\lib\\site-packages\\pandas\\io\\common.py\", line 789, in get_handle\n",
      "    handle = open(\n",
      "FileNotFoundError: [Errno 2] No such file or directory: '..\\\\assets\\\\usgs_3dep_metadata.csv'\n",
      "2022-06-24 23:36:50,477 — FileHandler — ERROR — usgs_3dep_metadata not found\n",
      "Traceback (most recent call last):\n",
      "  File \"c:\\Users\\user\\10-Accademy\\W7\\USGS_3DEP_Python_LIDAR\\scripts\\file_handler.py\", line 49, in read_csv\n",
      "    path = logger.DATAS_PATH / str(name + '.csv')\n",
      "  File \"c:\\Users\\user\\.conda\\envs\\pdalpy_n\\lib\\site-packages\\pandas\\util\\_decorators.py\", line 311, in wrapper\n",
      "    return func(*args, **kwargs)\n",
      "  File \"c:\\Users\\user\\.conda\\envs\\pdalpy_n\\lib\\site-packages\\pandas\\io\\parsers\\readers.py\", line 680, in read_csv\n",
      "    return _read(filepath_or_buffer, kwds)\n",
      "  File \"c:\\Users\\user\\.conda\\envs\\pdalpy_n\\lib\\site-packages\\pandas\\io\\parsers\\readers.py\", line 575, in _read\n",
      "    parser = TextFileReader(filepath_or_buffer, **kwds)\n",
      "  File \"c:\\Users\\user\\.conda\\envs\\pdalpy_n\\lib\\site-packages\\pandas\\io\\parsers\\readers.py\", line 933, in __init__\n",
      "    self._engine = self._make_engine(f, self.engine)\n",
      "  File \"c:\\Users\\user\\.conda\\envs\\pdalpy_n\\lib\\site-packages\\pandas\\io\\parsers\\readers.py\", line 1217, in _make_engine\n",
      "    self.handles = get_handle(  # type: ignore[call-overload]\n",
      "  File \"c:\\Users\\user\\.conda\\envs\\pdalpy_n\\lib\\site-packages\\pandas\\io\\common.py\", line 789, in get_handle\n",
      "    handle = open(\n",
      "FileNotFoundError: [Errno 2] No such file or directory: '..\\\\assets\\\\usgs_3dep_metadata.csv'\n",
      "2022-06-24 23:36:50,477 — FileHandler — ERROR — usgs_3dep_metadata not found\n",
      "Traceback (most recent call last):\n",
      "  File \"c:\\Users\\user\\10-Accademy\\W7\\USGS_3DEP_Python_LIDAR\\scripts\\file_handler.py\", line 49, in read_csv\n",
      "    path = logger.DATAS_PATH / str(name + '.csv')\n",
      "  File \"c:\\Users\\user\\.conda\\envs\\pdalpy_n\\lib\\site-packages\\pandas\\util\\_decorators.py\", line 311, in wrapper\n",
      "    return func(*args, **kwargs)\n",
      "  File \"c:\\Users\\user\\.conda\\envs\\pdalpy_n\\lib\\site-packages\\pandas\\io\\parsers\\readers.py\", line 680, in read_csv\n",
      "    return _read(filepath_or_buffer, kwds)\n",
      "  File \"c:\\Users\\user\\.conda\\envs\\pdalpy_n\\lib\\site-packages\\pandas\\io\\parsers\\readers.py\", line 575, in _read\n",
      "    parser = TextFileReader(filepath_or_buffer, **kwds)\n",
      "  File \"c:\\Users\\user\\.conda\\envs\\pdalpy_n\\lib\\site-packages\\pandas\\io\\parsers\\readers.py\", line 933, in __init__\n",
      "    self._engine = self._make_engine(f, self.engine)\n",
      "  File \"c:\\Users\\user\\.conda\\envs\\pdalpy_n\\lib\\site-packages\\pandas\\io\\parsers\\readers.py\", line 1217, in _make_engine\n",
      "    self.handles = get_handle(  # type: ignore[call-overload]\n",
      "  File \"c:\\Users\\user\\.conda\\envs\\pdalpy_n\\lib\\site-packages\\pandas\\io\\common.py\", line 789, in get_handle\n",
      "    handle = open(\n",
      "FileNotFoundError: [Errno 2] No such file or directory: '..\\\\assets\\\\usgs_3dep_metadata.csv'\n",
      "2022-06-24 23:36:50,477 — FileHandler — ERROR — usgs_3dep_metadata not found\n",
      "Traceback (most recent call last):\n",
      "  File \"c:\\Users\\user\\10-Accademy\\W7\\USGS_3DEP_Python_LIDAR\\scripts\\file_handler.py\", line 49, in read_csv\n",
      "    path = logger.DATAS_PATH / str(name + '.csv')\n",
      "  File \"c:\\Users\\user\\.conda\\envs\\pdalpy_n\\lib\\site-packages\\pandas\\util\\_decorators.py\", line 311, in wrapper\n",
      "    return func(*args, **kwargs)\n",
      "  File \"c:\\Users\\user\\.conda\\envs\\pdalpy_n\\lib\\site-packages\\pandas\\io\\parsers\\readers.py\", line 680, in read_csv\n",
      "    return _read(filepath_or_buffer, kwds)\n",
      "  File \"c:\\Users\\user\\.conda\\envs\\pdalpy_n\\lib\\site-packages\\pandas\\io\\parsers\\readers.py\", line 575, in _read\n",
      "    parser = TextFileReader(filepath_or_buffer, **kwds)\n",
      "  File \"c:\\Users\\user\\.conda\\envs\\pdalpy_n\\lib\\site-packages\\pandas\\io\\parsers\\readers.py\", line 933, in __init__\n",
      "    self._engine = self._make_engine(f, self.engine)\n",
      "  File \"c:\\Users\\user\\.conda\\envs\\pdalpy_n\\lib\\site-packages\\pandas\\io\\parsers\\readers.py\", line 1217, in _make_engine\n",
      "    self.handles = get_handle(  # type: ignore[call-overload]\n",
      "  File \"c:\\Users\\user\\.conda\\envs\\pdalpy_n\\lib\\site-packages\\pandas\\io\\common.py\", line 789, in get_handle\n",
      "    handle = open(\n",
      "FileNotFoundError: [Errno 2] No such file or directory: '..\\\\assets\\\\usgs_3dep_metadata.csv'\n",
      "2022-06-24 23:36:50,477 — FileHandler — ERROR — usgs_3dep_metadata not found\n",
      "Traceback (most recent call last):\n",
      "  File \"c:\\Users\\user\\10-Accademy\\W7\\USGS_3DEP_Python_LIDAR\\scripts\\file_handler.py\", line 49, in read_csv\n",
      "    path = logger.DATAS_PATH / str(name + '.csv')\n",
      "  File \"c:\\Users\\user\\.conda\\envs\\pdalpy_n\\lib\\site-packages\\pandas\\util\\_decorators.py\", line 311, in wrapper\n",
      "    return func(*args, **kwargs)\n",
      "  File \"c:\\Users\\user\\.conda\\envs\\pdalpy_n\\lib\\site-packages\\pandas\\io\\parsers\\readers.py\", line 680, in read_csv\n",
      "    return _read(filepath_or_buffer, kwds)\n",
      "  File \"c:\\Users\\user\\.conda\\envs\\pdalpy_n\\lib\\site-packages\\pandas\\io\\parsers\\readers.py\", line 575, in _read\n",
      "    parser = TextFileReader(filepath_or_buffer, **kwds)\n",
      "  File \"c:\\Users\\user\\.conda\\envs\\pdalpy_n\\lib\\site-packages\\pandas\\io\\parsers\\readers.py\", line 933, in __init__\n",
      "    self._engine = self._make_engine(f, self.engine)\n",
      "  File \"c:\\Users\\user\\.conda\\envs\\pdalpy_n\\lib\\site-packages\\pandas\\io\\parsers\\readers.py\", line 1217, in _make_engine\n",
      "    self.handles = get_handle(  # type: ignore[call-overload]\n",
      "  File \"c:\\Users\\user\\.conda\\envs\\pdalpy_n\\lib\\site-packages\\pandas\\io\\common.py\", line 789, in get_handle\n",
      "    handle = open(\n",
      "FileNotFoundError: [Errno 2] No such file or directory: '..\\\\assets\\\\usgs_3dep_metadata.csv'\n",
      "2022-06-24 23:36:50,477 — FileHandler — ERROR — usgs_3dep_metadata not found\n",
      "Traceback (most recent call last):\n",
      "  File \"c:\\Users\\user\\10-Accademy\\W7\\USGS_3DEP_Python_LIDAR\\scripts\\file_handler.py\", line 49, in read_csv\n",
      "    path = logger.DATAS_PATH / str(name + '.csv')\n",
      "  File \"c:\\Users\\user\\.conda\\envs\\pdalpy_n\\lib\\site-packages\\pandas\\util\\_decorators.py\", line 311, in wrapper\n",
      "    return func(*args, **kwargs)\n",
      "  File \"c:\\Users\\user\\.conda\\envs\\pdalpy_n\\lib\\site-packages\\pandas\\io\\parsers\\readers.py\", line 680, in read_csv\n",
      "    return _read(filepath_or_buffer, kwds)\n",
      "  File \"c:\\Users\\user\\.conda\\envs\\pdalpy_n\\lib\\site-packages\\pandas\\io\\parsers\\readers.py\", line 575, in _read\n",
      "    parser = TextFileReader(filepath_or_buffer, **kwds)\n",
      "  File \"c:\\Users\\user\\.conda\\envs\\pdalpy_n\\lib\\site-packages\\pandas\\io\\parsers\\readers.py\", line 933, in __init__\n",
      "    self._engine = self._make_engine(f, self.engine)\n",
      "  File \"c:\\Users\\user\\.conda\\envs\\pdalpy_n\\lib\\site-packages\\pandas\\io\\parsers\\readers.py\", line 1217, in _make_engine\n",
      "    self.handles = get_handle(  # type: ignore[call-overload]\n",
      "  File \"c:\\Users\\user\\.conda\\envs\\pdalpy_n\\lib\\site-packages\\pandas\\io\\common.py\", line 789, in get_handle\n",
      "    handle = open(\n",
      "FileNotFoundError: [Errno 2] No such file or directory: '..\\\\assets\\\\usgs_3dep_metadata.csv'\n",
      "2022-06-24 23:36:50,477 — FileHandler — ERROR — usgs_3dep_metadata not found\n",
      "Traceback (most recent call last):\n",
      "  File \"c:\\Users\\user\\10-Accademy\\W7\\USGS_3DEP_Python_LIDAR\\scripts\\file_handler.py\", line 49, in read_csv\n",
      "    path = logger.DATAS_PATH / str(name + '.csv')\n",
      "  File \"c:\\Users\\user\\.conda\\envs\\pdalpy_n\\lib\\site-packages\\pandas\\util\\_decorators.py\", line 311, in wrapper\n",
      "    return func(*args, **kwargs)\n",
      "  File \"c:\\Users\\user\\.conda\\envs\\pdalpy_n\\lib\\site-packages\\pandas\\io\\parsers\\readers.py\", line 680, in read_csv\n",
      "    return _read(filepath_or_buffer, kwds)\n",
      "  File \"c:\\Users\\user\\.conda\\envs\\pdalpy_n\\lib\\site-packages\\pandas\\io\\parsers\\readers.py\", line 575, in _read\n",
      "    parser = TextFileReader(filepath_or_buffer, **kwds)\n",
      "  File \"c:\\Users\\user\\.conda\\envs\\pdalpy_n\\lib\\site-packages\\pandas\\io\\parsers\\readers.py\", line 933, in __init__\n",
      "    self._engine = self._make_engine(f, self.engine)\n",
      "  File \"c:\\Users\\user\\.conda\\envs\\pdalpy_n\\lib\\site-packages\\pandas\\io\\parsers\\readers.py\", line 1217, in _make_engine\n",
      "    self.handles = get_handle(  # type: ignore[call-overload]\n",
      "  File \"c:\\Users\\user\\.conda\\envs\\pdalpy_n\\lib\\site-packages\\pandas\\io\\common.py\", line 789, in get_handle\n",
      "    handle = open(\n",
      "FileNotFoundError: [Errno 2] No such file or directory: '..\\\\assets\\\\usgs_3dep_metadata.csv'\n",
      "2022-06-24 23:36:50,477 — FileHandler — ERROR — usgs_3dep_metadata not found\n",
      "Traceback (most recent call last):\n",
      "  File \"c:\\Users\\user\\10-Accademy\\W7\\USGS_3DEP_Python_LIDAR\\scripts\\file_handler.py\", line 49, in read_csv\n",
      "    path = logger.DATAS_PATH / str(name + '.csv')\n",
      "  File \"c:\\Users\\user\\.conda\\envs\\pdalpy_n\\lib\\site-packages\\pandas\\util\\_decorators.py\", line 311, in wrapper\n",
      "    return func(*args, **kwargs)\n",
      "  File \"c:\\Users\\user\\.conda\\envs\\pdalpy_n\\lib\\site-packages\\pandas\\io\\parsers\\readers.py\", line 680, in read_csv\n",
      "    return _read(filepath_or_buffer, kwds)\n",
      "  File \"c:\\Users\\user\\.conda\\envs\\pdalpy_n\\lib\\site-packages\\pandas\\io\\parsers\\readers.py\", line 575, in _read\n",
      "    parser = TextFileReader(filepath_or_buffer, **kwds)\n",
      "  File \"c:\\Users\\user\\.conda\\envs\\pdalpy_n\\lib\\site-packages\\pandas\\io\\parsers\\readers.py\", line 933, in __init__\n",
      "    self._engine = self._make_engine(f, self.engine)\n",
      "  File \"c:\\Users\\user\\.conda\\envs\\pdalpy_n\\lib\\site-packages\\pandas\\io\\parsers\\readers.py\", line 1217, in _make_engine\n",
      "    self.handles = get_handle(  # type: ignore[call-overload]\n",
      "  File \"c:\\Users\\user\\.conda\\envs\\pdalpy_n\\lib\\site-packages\\pandas\\io\\common.py\", line 789, in get_handle\n",
      "    handle = open(\n",
      "FileNotFoundError: [Errno 2] No such file or directory: '..\\\\assets\\\\usgs_3dep_metadata.csv'\n",
      "2022-06-24 23:36:50,477 — FileHandler — ERROR — usgs_3dep_metadata not found\n",
      "Traceback (most recent call last):\n",
      "  File \"c:\\Users\\user\\10-Accademy\\W7\\USGS_3DEP_Python_LIDAR\\scripts\\file_handler.py\", line 49, in read_csv\n",
      "    path = logger.DATAS_PATH / str(name + '.csv')\n",
      "  File \"c:\\Users\\user\\.conda\\envs\\pdalpy_n\\lib\\site-packages\\pandas\\util\\_decorators.py\", line 311, in wrapper\n",
      "    return func(*args, **kwargs)\n",
      "  File \"c:\\Users\\user\\.conda\\envs\\pdalpy_n\\lib\\site-packages\\pandas\\io\\parsers\\readers.py\", line 680, in read_csv\n",
      "    return _read(filepath_or_buffer, kwds)\n",
      "  File \"c:\\Users\\user\\.conda\\envs\\pdalpy_n\\lib\\site-packages\\pandas\\io\\parsers\\readers.py\", line 575, in _read\n",
      "    parser = TextFileReader(filepath_or_buffer, **kwds)\n",
      "  File \"c:\\Users\\user\\.conda\\envs\\pdalpy_n\\lib\\site-packages\\pandas\\io\\parsers\\readers.py\", line 933, in __init__\n",
      "    self._engine = self._make_engine(f, self.engine)\n",
      "  File \"c:\\Users\\user\\.conda\\envs\\pdalpy_n\\lib\\site-packages\\pandas\\io\\parsers\\readers.py\", line 1217, in _make_engine\n",
      "    self.handles = get_handle(  # type: ignore[call-overload]\n",
      "  File \"c:\\Users\\user\\.conda\\envs\\pdalpy_n\\lib\\site-packages\\pandas\\io\\common.py\", line 789, in get_handle\n",
      "    handle = open(\n",
      "FileNotFoundError: [Errno 2] No such file or directory: '..\\\\assets\\\\usgs_3dep_metadata.csv'\n",
      "2022-06-24 23:36:50,477 — FileHandler — ERROR — usgs_3dep_metadata not found\n",
      "Traceback (most recent call last):\n",
      "  File \"c:\\Users\\user\\10-Accademy\\W7\\USGS_3DEP_Python_LIDAR\\scripts\\file_handler.py\", line 49, in read_csv\n",
      "    path = logger.DATAS_PATH / str(name + '.csv')\n",
      "  File \"c:\\Users\\user\\.conda\\envs\\pdalpy_n\\lib\\site-packages\\pandas\\util\\_decorators.py\", line 311, in wrapper\n",
      "    return func(*args, **kwargs)\n",
      "  File \"c:\\Users\\user\\.conda\\envs\\pdalpy_n\\lib\\site-packages\\pandas\\io\\parsers\\readers.py\", line 680, in read_csv\n",
      "    return _read(filepath_or_buffer, kwds)\n",
      "  File \"c:\\Users\\user\\.conda\\envs\\pdalpy_n\\lib\\site-packages\\pandas\\io\\parsers\\readers.py\", line 575, in _read\n",
      "    parser = TextFileReader(filepath_or_buffer, **kwds)\n",
      "  File \"c:\\Users\\user\\.conda\\envs\\pdalpy_n\\lib\\site-packages\\pandas\\io\\parsers\\readers.py\", line 933, in __init__\n",
      "    self._engine = self._make_engine(f, self.engine)\n",
      "  File \"c:\\Users\\user\\.conda\\envs\\pdalpy_n\\lib\\site-packages\\pandas\\io\\parsers\\readers.py\", line 1217, in _make_engine\n",
      "    self.handles = get_handle(  # type: ignore[call-overload]\n",
      "  File \"c:\\Users\\user\\.conda\\envs\\pdalpy_n\\lib\\site-packages\\pandas\\io\\common.py\", line 789, in get_handle\n",
      "    handle = open(\n",
      "FileNotFoundError: [Errno 2] No such file or directory: '..\\\\assets\\\\usgs_3dep_metadata.csv'\n",
      "2022-06-24 23:36:50,477 — FileHandler — ERROR — usgs_3dep_metadata not found\n",
      "Traceback (most recent call last):\n",
      "  File \"c:\\Users\\user\\10-Accademy\\W7\\USGS_3DEP_Python_LIDAR\\scripts\\file_handler.py\", line 49, in read_csv\n",
      "    path = logger.DATAS_PATH / str(name + '.csv')\n",
      "  File \"c:\\Users\\user\\.conda\\envs\\pdalpy_n\\lib\\site-packages\\pandas\\util\\_decorators.py\", line 311, in wrapper\n",
      "    return func(*args, **kwargs)\n",
      "  File \"c:\\Users\\user\\.conda\\envs\\pdalpy_n\\lib\\site-packages\\pandas\\io\\parsers\\readers.py\", line 680, in read_csv\n",
      "    return _read(filepath_or_buffer, kwds)\n",
      "  File \"c:\\Users\\user\\.conda\\envs\\pdalpy_n\\lib\\site-packages\\pandas\\io\\parsers\\readers.py\", line 575, in _read\n",
      "    parser = TextFileReader(filepath_or_buffer, **kwds)\n",
      "  File \"c:\\Users\\user\\.conda\\envs\\pdalpy_n\\lib\\site-packages\\pandas\\io\\parsers\\readers.py\", line 933, in __init__\n",
      "    self._engine = self._make_engine(f, self.engine)\n",
      "  File \"c:\\Users\\user\\.conda\\envs\\pdalpy_n\\lib\\site-packages\\pandas\\io\\parsers\\readers.py\", line 1217, in _make_engine\n",
      "    self.handles = get_handle(  # type: ignore[call-overload]\n",
      "  File \"c:\\Users\\user\\.conda\\envs\\pdalpy_n\\lib\\site-packages\\pandas\\io\\common.py\", line 789, in get_handle\n",
      "    handle = open(\n",
      "FileNotFoundError: [Errno 2] No such file or directory: '..\\\\assets\\\\usgs_3dep_metadata.csv'\n",
      "2022-06-24 23:36:50,477 — FileHandler — ERROR — usgs_3dep_metadata not found\n",
      "Traceback (most recent call last):\n",
      "  File \"c:\\Users\\user\\10-Accademy\\W7\\USGS_3DEP_Python_LIDAR\\scripts\\file_handler.py\", line 49, in read_csv\n",
      "    path = logger.DATAS_PATH / str(name + '.csv')\n",
      "  File \"c:\\Users\\user\\.conda\\envs\\pdalpy_n\\lib\\site-packages\\pandas\\util\\_decorators.py\", line 311, in wrapper\n",
      "    return func(*args, **kwargs)\n",
      "  File \"c:\\Users\\user\\.conda\\envs\\pdalpy_n\\lib\\site-packages\\pandas\\io\\parsers\\readers.py\", line 680, in read_csv\n",
      "    return _read(filepath_or_buffer, kwds)\n",
      "  File \"c:\\Users\\user\\.conda\\envs\\pdalpy_n\\lib\\site-packages\\pandas\\io\\parsers\\readers.py\", line 575, in _read\n",
      "    parser = TextFileReader(filepath_or_buffer, **kwds)\n",
      "  File \"c:\\Users\\user\\.conda\\envs\\pdalpy_n\\lib\\site-packages\\pandas\\io\\parsers\\readers.py\", line 933, in __init__\n",
      "    self._engine = self._make_engine(f, self.engine)\n",
      "  File \"c:\\Users\\user\\.conda\\envs\\pdalpy_n\\lib\\site-packages\\pandas\\io\\parsers\\readers.py\", line 1217, in _make_engine\n",
      "    self.handles = get_handle(  # type: ignore[call-overload]\n",
      "  File \"c:\\Users\\user\\.conda\\envs\\pdalpy_n\\lib\\site-packages\\pandas\\io\\common.py\", line 789, in get_handle\n",
      "    handle = open(\n",
      "FileNotFoundError: [Errno 2] No such file or directory: '..\\\\assets\\\\usgs_3dep_metadata.csv'\n",
      "2022-06-24 23:36:50,477 — FileHandler — ERROR — usgs_3dep_metadata not found\n",
      "Traceback (most recent call last):\n",
      "  File \"c:\\Users\\user\\10-Accademy\\W7\\USGS_3DEP_Python_LIDAR\\scripts\\file_handler.py\", line 49, in read_csv\n",
      "    path = logger.DATAS_PATH / str(name + '.csv')\n",
      "  File \"c:\\Users\\user\\.conda\\envs\\pdalpy_n\\lib\\site-packages\\pandas\\util\\_decorators.py\", line 311, in wrapper\n",
      "    return func(*args, **kwargs)\n",
      "  File \"c:\\Users\\user\\.conda\\envs\\pdalpy_n\\lib\\site-packages\\pandas\\io\\parsers\\readers.py\", line 680, in read_csv\n",
      "    return _read(filepath_or_buffer, kwds)\n",
      "  File \"c:\\Users\\user\\.conda\\envs\\pdalpy_n\\lib\\site-packages\\pandas\\io\\parsers\\readers.py\", line 575, in _read\n",
      "    parser = TextFileReader(filepath_or_buffer, **kwds)\n",
      "  File \"c:\\Users\\user\\.conda\\envs\\pdalpy_n\\lib\\site-packages\\pandas\\io\\parsers\\readers.py\", line 933, in __init__\n",
      "    self._engine = self._make_engine(f, self.engine)\n",
      "  File \"c:\\Users\\user\\.conda\\envs\\pdalpy_n\\lib\\site-packages\\pandas\\io\\parsers\\readers.py\", line 1217, in _make_engine\n",
      "    self.handles = get_handle(  # type: ignore[call-overload]\n",
      "  File \"c:\\Users\\user\\.conda\\envs\\pdalpy_n\\lib\\site-packages\\pandas\\io\\common.py\", line 789, in get_handle\n",
      "    handle = open(\n",
      "FileNotFoundError: [Errno 2] No such file or directory: '..\\\\assets\\\\usgs_3dep_metadata.csv'\n",
      "2022-06-24 23:36:50,477 — FileHandler — ERROR — usgs_3dep_metadata not found\n",
      "Traceback (most recent call last):\n",
      "  File \"c:\\Users\\user\\10-Accademy\\W7\\USGS_3DEP_Python_LIDAR\\scripts\\file_handler.py\", line 49, in read_csv\n",
      "    path = logger.DATAS_PATH / str(name + '.csv')\n",
      "  File \"c:\\Users\\user\\.conda\\envs\\pdalpy_n\\lib\\site-packages\\pandas\\util\\_decorators.py\", line 311, in wrapper\n",
      "    return func(*args, **kwargs)\n",
      "  File \"c:\\Users\\user\\.conda\\envs\\pdalpy_n\\lib\\site-packages\\pandas\\io\\parsers\\readers.py\", line 680, in read_csv\n",
      "    return _read(filepath_or_buffer, kwds)\n",
      "  File \"c:\\Users\\user\\.conda\\envs\\pdalpy_n\\lib\\site-packages\\pandas\\io\\parsers\\readers.py\", line 575, in _read\n",
      "    parser = TextFileReader(filepath_or_buffer, **kwds)\n",
      "  File \"c:\\Users\\user\\.conda\\envs\\pdalpy_n\\lib\\site-packages\\pandas\\io\\parsers\\readers.py\", line 933, in __init__\n",
      "    self._engine = self._make_engine(f, self.engine)\n",
      "  File \"c:\\Users\\user\\.conda\\envs\\pdalpy_n\\lib\\site-packages\\pandas\\io\\parsers\\readers.py\", line 1217, in _make_engine\n",
      "    self.handles = get_handle(  # type: ignore[call-overload]\n",
      "  File \"c:\\Users\\user\\.conda\\envs\\pdalpy_n\\lib\\site-packages\\pandas\\io\\common.py\", line 789, in get_handle\n",
      "    handle = open(\n",
      "FileNotFoundError: [Errno 2] No such file or directory: '..\\\\assets\\\\usgs_3dep_metadata.csv'\n"
     ]
    }
   ],
   "source": [
    "pl = PythonLidar(epsg=3857)"
   ]
  },
  {
   "cell_type": "code",
   "execution_count": 3,
   "metadata": {},
   "outputs": [
    {
     "data": {
      "text/plain": [
       "<LasData(1.2, point fmt: <PointFormat(1, 5 bytes of extra dims)>, 27029 points, 3 vlrs)>"
      ]
     },
     "execution_count": 3,
     "metadata": {},
     "output_type": "execute_result"
    }
   ],
   "source": [
    "las = laspy.read('../data/ept-data/10-0-833-513.laz')\n",
    "las"
   ]
  },
  {
   "cell_type": "code",
   "execution_count": 5,
   "metadata": {},
   "outputs": [
    {
     "data": {
      "text/plain": [
       "[<ExtraBytesVlr(extra bytes structs: 2)>, <GeoKeyDirectoryVlr(7 geo_keys)>, <GeoAsciiParamsVlr(['WGS 84 / Pseudo-Mercator|WGS 84|', ''])>]"
      ]
     },
     "execution_count": 5,
     "metadata": {},
     "output_type": "execute_result"
    }
   ],
   "source": [
    "las.header\n",
    "las.header.point_format\n",
    "las.header.point_count\n",
    "las.vlrs"
   ]
  },
  {
   "cell_type": "code",
   "execution_count": 6,
   "metadata": {},
   "outputs": [
    {
     "data": {
      "text/plain": [
       "['X',\n",
       " 'Y',\n",
       " 'Z',\n",
       " 'intensity',\n",
       " 'return_number',\n",
       " 'number_of_returns',\n",
       " 'scan_direction_flag',\n",
       " 'edge_of_flight_line',\n",
       " 'classification',\n",
       " 'synthetic',\n",
       " 'key_point',\n",
       " 'withheld',\n",
       " 'scan_angle_rank',\n",
       " 'user_data',\n",
       " 'point_source_id',\n",
       " 'gps_time',\n",
       " 'ClassFlags',\n",
       " 'OriginId']"
      ]
     },
     "execution_count": 6,
     "metadata": {},
     "output_type": "execute_result"
    }
   ],
   "source": [
    "list(las.point_format.dimension_names)"
   ]
  },
  {
   "cell_type": "code",
   "execution_count": 11,
   "metadata": {},
   "outputs": [
    {
     "name": "stdout",
     "output_type": "stream",
     "text": [
      "x= [-6834730 -6834747 -6834762 ... -6839794 -6839812 -6839794]\n",
      "intensity= [314 324 269 ... 144 249 290]\n",
      "coordinate = [1.99824630e+08 1.99824630e+08 1.99824630e+08 ... 1.99826321e+08\n",
      " 1.99826321e+08 1.99826321e+08]\n"
     ]
    }
   ],
   "source": [
    "print('x=',  las.X)\n",
    "print('intensity=', las.intensity)\n",
    "print('coordinate =', las.gps_time)"
   ]
  },
  {
   "cell_type": "code",
   "execution_count": 14,
   "metadata": {},
   "outputs": [],
   "source": [
    "# classes\n",
    "classes = set(list(las.classification))"
   ]
  },
  {
   "cell_type": "code",
   "execution_count": 15,
   "metadata": {},
   "outputs": [
    {
     "data": {
      "text/plain": [
       "array([[-6834730,  4292758,    14563],\n",
       "       [-6834747,  4292656,    14568],\n",
       "       [-6834762,  4292561,    14575],\n",
       "       ...,\n",
       "       [-6839794,  4305274,    13845],\n",
       "       [-6839812,  4305185,    13832],\n",
       "       [-6839794,  4305864,    13837]])"
      ]
     },
     "execution_count": 15,
     "metadata": {},
     "output_type": "execute_result"
    }
   ],
   "source": [
    "point_data = np.stack([las.X, las.Y, las.Z], axis=0).transpose((1, 0))\n",
    "point_data"
   ]
  },
  {
   "cell_type": "code",
   "execution_count": 16,
   "metadata": {},
   "outputs": [],
   "source": [
    "ground = laspy.create(point_format=las.header.point_format, file_version=las.header.version)\n",
    "ground.points = las.points[las.classification == 2]"
   ]
  },
  {
   "cell_type": "code",
   "execution_count": 18,
   "metadata": {},
   "outputs": [
    {
     "ename": "ImportError",
     "evalue": "cannot import name 'JVisualizer' from 'open3d' (c:\\Users\\user\\.conda\\envs\\pdalpy_n\\lib\\site-packages\\open3d\\__init__.py)",
     "output_type": "error",
     "traceback": [
      "\u001b[1;31m---------------------------------------------------------------------------\u001b[0m",
      "\u001b[1;31mImportError\u001b[0m                               Traceback (most recent call last)",
      "\u001b[1;32mc:\\Users\\user\\10-Accademy\\W7\\USGS_3DEP_Python_LIDAR\\example\\fetch_visual_lidar.ipynb Cell 11'\u001b[0m in \u001b[0;36m<cell line: 1>\u001b[1;34m()\u001b[0m\n\u001b[1;32m----> <a href='vscode-notebook-cell:/c%3A/Users/user/10-Accademy/W7/USGS_3DEP_Python_LIDAR/example/fetch_visual_lidar.ipynb#ch0000015?line=0'>1</a>\u001b[0m \u001b[39mfrom\u001b[39;00m \u001b[39mopen3d\u001b[39;00m \u001b[39mimport\u001b[39;00m JVisualizer\n",
      "\u001b[1;31mImportError\u001b[0m: cannot import name 'JVisualizer' from 'open3d' (c:\\Users\\user\\.conda\\envs\\pdalpy_n\\lib\\site-packages\\open3d\\__init__.py)"
     ]
    }
   ],
   "source": []
  },
  {
   "cell_type": "code",
   "execution_count": 25,
   "metadata": {},
   "outputs": [
    {
     "name": "stdout",
     "output_type": "stream",
     "text": [
      "[Open3D WARNING] [ViewControl] SetViewPoint() failed because window height and width are not set.\n"
     ]
    }
   ],
   "source": [
    "geom = o3d.geometry.PointCloud()\n",
    "geom.points = o3d.utility.Vector3dVector(point_data)\n",
    "o3d.visualization.draw_geometries([geom])"
   ]
  },
  {
   "cell_type": "code",
   "execution_count": null,
   "metadata": {},
   "outputs": [],
   "source": []
  },
  {
   "cell_type": "code",
   "execution_count": null,
   "metadata": {},
   "outputs": [],
   "source": []
  },
  {
   "cell_type": "code",
   "execution_count": null,
   "metadata": {},
   "outputs": [],
   "source": []
  },
  {
   "cell_type": "code",
   "execution_count": null,
   "metadata": {},
   "outputs": [],
   "source": []
  },
  {
   "cell_type": "code",
   "execution_count": null,
   "metadata": {},
   "outputs": [],
   "source": []
  },
  {
   "cell_type": "markdown",
   "metadata": {},
   "source": []
  }
 ],
 "metadata": {
  "kernelspec": {
   "display_name": "Python 3 (ipykernel)",
   "language": "python",
   "name": "python3"
  },
  "language_info": {
   "codemirror_mode": {
    "name": "ipython",
    "version": 3
   },
   "file_extension": ".py",
   "mimetype": "text/x-python",
   "name": "python",
   "nbconvert_exporter": "python",
   "pygments_lexer": "ipython3",
   "version": "3.9.12"
  },
  "vscode": {
   "interpreter": {
    "hash": "02583d2a41429db8f929c3bdc03bf7a9ecf6726f01e4eaed61ed388e4c32b860"
   }
  }
 },
 "nbformat": 4,
 "nbformat_minor": 2
}
